Workbook

Sheet Summary
A1: Paracetamol in water: how much is good vs bad?
A2: AquaTrace (KL Ocean Hackathon) · prepared 8 Oct 2026 · values in µg/L unless stated · 1 mg/L = 1,000 µg/L = 1,000,000 ng/L
A4: KEY SETTING
A5: PNEC used for risk (choose from the list) | B5: Albarano 2025
A6: PNEC value (µg/L) | B6: =INDEX(Thresholds!$F$5:$F$12,MATCH($B$5,Thresholds!$B$5:$B$12,0)) -> 10 | C6: PNEC = predicted no-effect concentration: below it, aquatic life should be safe.
A7: Human drinking-water limit (µg/L) | B7: =Thresholds!$F$11 -> 175 | C7: Australian Guidelines for Water Recycling 2008 (human health, drinking water).
A9: RISK BANDS (RQ = concentration ÷ PNEC; same rule as the AquaTrace website)
A10: Band | B10: RQ range | C10: From (µg/L) | D10: To (µg/L) | E10: From (mg/L) | F10: To (mg/L) | G10: What it means
A11: Low | B11: RQ < 0.1 | C11: 0 | D11: =0.1*$B$6 -> 1 | E11: =C11/1000 -> 0 | F11: =IF(ISNUMBER(D11),D11/1000,"and above") -> 0.001 | G11: Normal river water
A12: Medium | B12: 0.1 ≤ RQ < 1 | C12: =0.1*$B$6 -> 1 | D12: =$B$6 -> 10 | E12: =C12/1000 -> 0.001 | F12: =IF(ISNUMBER(D12),D12/1000,"and above") -> 0.01 | G12: Sewage-impacted water: keep watching
A13: High | B13: RQ ≥ 1 | C13: =$B$6 -> 10 | D13: and above | E13: =C13/1000 -> 0.01 | F13: =IF(ISNUMBER(D13),D13/1000,"and above") -> and above | G13: Risk to aquatic life: confirm by HPLC and find the source
A15: ONE-LINE ANSWER
A16: ="Good: below "&ROUND(0.1*$B$6,3)&" µg/L · Warning: "&ROUND(0.1*$B$6,3)&"–"&ROUND($B$6,3)&" µg/L · Bad: "&ROUND($B$6,3)&" µg/L or more (PNEC, "&$B$5&")" -> Good: below 1 µg/L · Warning: 1–10 µg/L · Bad: 10 µg/L or more (PNEC, Albarano 2025)
A17: Paracetamol has never been measured in Penang (the 4 USM theses measured atenolol, carbamazepine, diclofenac and ketoprofen only). The team's CenFac HPLC results will be the first Penang data.
A19: CONCENTRATION LADDER (µg/L, log scale in the chart)
A20: Level | B20: µg/L | C20: Type
A21: US rivers: median detection | B21: =Measured_Levels!$G$5 -> 0.042 | C21: Measured
A22: Langat River (Malaysia): max | B22: =Measured_Levels!$G$9 -> 0.3463 | C22: Measured
A23: US rivers: 99th percentile | B23: =Measured_Levels!$G$7 -> 5.258 | C23: Measured
A24: PNEC (chosen above) | B24: =$B$6 -> 10 | C24: Threshold
A25: Hospital WWTP influent max (Saudi) | B25: =Measured_Levels!$G$11 -> 12.39 | C25: Measured
A26: NORMAN PNEC | B26: =Thresholds!$F$7 -> 46 | C26: Threshold
A27: HC5: 5% of species affected | B27: =Thresholds!$F$6 -> 50 | C27: Threshold
A28: Website screening level (current) | B28: =Website_Check!$D$5 -> 150 | C28: Website
A29: Drinking-water limit (AGWR 2008) | B29: =$B$7 -> 175 | C29: Threshold
A30: Municipal WWTP influent (India) | B30: =Measured_Levels!$G$13 -> 4600 | C30: Measured
A31: Daphnia acute LC50 (48 h) | B31: =Thresholds!$F$10 -> 16900 | C31: Threshold
A33: HOW TO USE THIS WORKBOOK
A34: Blue text | B34: An input you can change.
A35: Yellow fill | B35: The key setting (PNEC choice).
A36: Black text | B36: Calculated by a formula. Do not type over it.
A37: Thresholds | B37: Safe limits for aquatic life and drinking water, with sources.
A38: Measured_Levels | B38: Real measured concentrations (rivers, wastewater, hospital).
A39: Risk_Calculator | B39: Type any concentration and unit → µg/L, RQ and risk band.
A40: Website_Check | B40: Phi's website values for paracetamol vs the literature.
A41: Lab_Design | B41: CenFac standards: concentrations, which instrument, dilution volumes.
A42: Results_Log | B42: Record pH, conductivity, UV and HPLC results per standard.
A43: Instrument_Limits | B43: What UV-Vis and HPLC-UV can detect.
A44: Sources | B44: Every reference with its link.

Sheet Thresholds
A1: Thresholds: how much paracetamol is too much?
A2: Aquatic-life limits (PNEC, HC5) are much stricter than human drinking-water limits. Values differ because studies use different species, endpoints and safety factors.
A4: # | B4: Short name | C4: Threshold | D4: Value | E4: Unit | F4: Value (µg/L) | G4: Protects | H4: Basis | I4: Source | J4: Link
A5: 1 | B5: Albarano 2025 | C5: PNEC, aquatic life (newest) | D5: 0.01 | E5: mg/L | F5: =IF(D5="","",D5*IF(E5="ng/L",0.001,IF(E5="mg/L",1000,1))) -> 10 | G5: Aquatic life (long-term) | H5: Species sensitivity distribution, 55 aquatic species (EC10), global occurrence data | I5: Albarano et al. 2025, Journal of Hazardous Materials, doi 10.1016/j.jhazmat.2025.140107 | J5: https://www.iris.unisa.it/handle/11386/4949119
A6: 2 | B6: Albarano 2025 HC5 | C6: HC5: concentration harming 5% of species | D6: 0.05 | E6: mg/L | F6: =IF(D6="","",D6*IF(E6="ng/L",0.001,IF(E6="mg/L",1000,1))) -> 50 | G6: Aquatic life | H6: Same species sensitivity distribution | I6: Albarano et al. 2025 | J6: https://www.iris.unisa.it/handle/11386/4949119
A7: 3 | B7: NORMAN | C7: PNEC, lowest long-term freshwater | D7: 46 | E7: µg/L | F7: =IF(D7="","",D7*IF(E7="ng/L",0.001,IF(E7="mg/L",1000,1))) -> 46 | G7: Aquatic life (long-term) | H7: NORMAN ecotoxicology database | I7: Environmental Sciences Europe 2024, Table 4 (NORMAN PNECs) | J7: https://enveurope.springeropen.com/articles/10.1186/s12302-024-01015-3/tables/4
A8: 4 | B8: Shipingana 2022 | C8: PNEC used in a WWTP risk study | D8: 12.9 | E8: µg/L | F8: =IF(D8="","",D8*IF(E8="ng/L",0.001,IF(E8="mg/L",1000,1))) -> 12.9 | G8: Aquatic life | H8: Based on Daphnia magna sensitivity | I8: Shipingana et al. 2022, Applied Water Science | J8: https://link.springer.com/article/10.1007/s13201-022-01570-1
A9: 5 | B9: Fan 2022 | C9: Chronic HC5 (older estimate) | D9: 1.21 | E9: mg/L | F9: =IF(D9="","",D9*IF(E9="ng/L",0.001,IF(E9="mg/L",1000,1))) -> 1210 | G9: Aquatic life | H9: Species sensitivity distribution, 9 chronic datasets (shows how much estimates vary) | I9: Fan et al. 2022, PNECs for 35 PPCPs in freshwater | J9: https://www.frontiersin.org/journals/marine-science/articles/10.3389/fmars.2022.1043792/pdf
A10: 6 | B10: Kim 2006 | C10: Acute LC50, Daphnia magna, 48 h | D10: 16.9 | E10: mg/L | F10: =IF(D10="","",D10*IF(E10="ng/L",0.001,IF(E10="mg/L",1000,1))) -> 16900 | G10: Acute lethality (short-term) | H10: Half of the test animals die in 48 h | I10: Kim 2006, Journal of Environmental Health Sciences (Korea) | J10: https://www.koreascience.or.kr/article/JAKO200604623620474.page?lang=en
A11: 7 | B11: AGWR 2008 | C11: Drinking-water guideline | D11: 175 | E11: µg/L | F11: =IF(D11="","",D11*IF(E11="ng/L",0.001,IF(E11="mg/L",1000,1))) -> 175 | G11: Human health | H11: Australian Guidelines for Water Recycling 2008 (augmentation of drinking water) | I11: EPA Victoria 2023, Appendix A, Table 12 | J11: https://app.production.epa-vic-gov-au.sdp3.sdp.vic.gov.au/sites/default/files/epa/publications/appendix_a_emerging-contaminants-in-recycled-water_31may2023.pdf
A12: 8 | B12: Minnesota 2015 | C12: Drinking-water guidance | D12: 200 | E12: µg/L | F12: =IF(D12="","",D12*IF(E12="ng/L",0.001,IF(E12="mg/L",1000,1))) -> 200 | G12: Human health | H12: Health-based value, all exposure durations | I12: Minnesota Department of Health, 2015 | J12: https://www.health.mn.gov/communities/environment/risk/docs/guidance/dwec/sumacetamin.pdf
A14: Why use 10 µg/L? It is the newest estimate (2025) and the most protective. Report 46 µg/L (NORMAN) as the alternative. Change the choice on the Summary sheet.

Sheet Measured_Levels
A1: Measured paracetamol levels: where does real water fall?
A2: RQ and risk band use the PNEC chosen on the Summary sheet. Blank value = not detected or not measured.
A4: # | B4: Water type | C4: Place | D4: Statistic | E4: Value | F4: Unit | G4: Value (µg/L) | H4: RQ (vs chosen PNEC) | I4: Risk band | J4: Above drinking-water limit? | K4: Source | L4: Link | M4: Note
A5: 1 | B5: River | C5: USA, 15,854 river site-days (detected in 6%) | D5: Median of detections | E5: 42 | F5: ng/L | G5: =IF(E5="","",E5*IF(F5="ng/L",0.001,IF(F5="mg/L",1000,1))) -> 0.042 | H5: =IF(G5="","",G5/Summary!$B$6) -> 0.0042 | I5: =IF(H5="","",IF(H5<0.1,"Low",IF(H5<1,"Medium","High"))) -> Low | J5: =IF(G5="","",IF(G5>=Summary!$B$7,"Yes","No")) -> No | K5: AquaTrace analysis of US Water Quality Portal data (wqp_paired_streams.csv) | L5: https://www.waterqualitydata.us/ | M5: Used as the "typical river" level
A6: 2 | B6: River | C6: USA | D6: 90th percentile of detections | E6: 298.9 | F6: ng/L | G6: =IF(E6="","",E6*IF(F6="ng/L",0.001,IF(F6="mg/L",1000,1))) -> 0.2989 | H6: =IF(G6="","",G6/Summary!$B$6) -> 0.02989 | I6: =IF(H6="","",IF(H6<0.1,"Low",IF(H6<1,"Medium","High"))) -> Low | J6: =IF(G6="","",IF(G6>=Summary!$B$7,"Yes","No")) -> No | K6: AquaTrace analysis of US Water Quality Portal data (wqp_paired_streams.csv) | L6: https://www.waterqualitydata.us/
A7: 3 | B7: River | C7: USA | D7: 99th percentile of detections | E7: 5258 | F7: ng/L | G7: =IF(E7="","",E7*IF(F7="ng/L",0.001,IF(F7="mg/L",1000,1))) -> 5.258 | H7: =IF(G7="","",G7/Summary!$B$6) -> 0.5258 | I7: =IF(H7="","",IF(H7<0.1,"Low",IF(H7<1,"Medium","High"))) -> Medium | J7: =IF(G7="","",IF(G7>=Summary!$B$7,"Yes","No")) -> No | K7: AquaTrace analysis of US Water Quality Portal data (wqp_paired_streams.csv) | L7: https://www.waterqualitydata.us/
A8: 4 | B8: River | C8: USA | D8: Maximum | E8: 76000 | F8: ng/L | G8: =IF(E8="","",E8*IF(F8="ng/L",0.001,IF(F8="mg/L",1000,1))) -> 76 | H8: =IF(G8="","",G8/Summary!$B$6) -> 7.6 | I8: =IF(H8="","",IF(H8<0.1,"Low",IF(H8<1,"Medium","High"))) -> High | J8: =IF(G8="","",IF(G8>=Summary!$B$7,"Yes","No")) -> No | K8: AquaTrace analysis of US Water Quality Portal data (wqp_paired_streams.csv) | L8: https://www.waterqualitydata.us/ | M8: Only 1 of 872 detections above 46 µg/L
A9: 5 | B9: River | C9: Langat River, Selangor, Malaysia | D9: Maximum | E9: 346.3 | F9: ng/L | G9: =IF(E9="","",E9*IF(F9="ng/L",0.001,IF(F9="mg/L",1000,1))) -> 0.3463 | H9: =IF(G9="","",G9/Summary!$B$6) -> 0.03463 | I9: =IF(H9="","",IF(H9<0.1,"Low",IF(H9<1,"Medium","High"))) -> Low | J9: =IF(G9="","",IF(G9>=Summary!$B$7,"Yes","No")) -> No | K9: Al-Odaini et al. 2013, Int. J. Environmental Analytical Chemistry | L9: https://www.ingentaconnect.com/content/tandf/geac/2013/00000093/00000003/art00001 | M9: Closest Malaysian river data
A10: 6 | B10: River | C10: Kyongahn River, Korea | D10: Measured | E10: 0.439 | F10: µg/L | G10: =IF(E10="","",E10*IF(F10="ng/L",0.001,IF(F10="mg/L",1000,1))) -> 0.439 | H10: =IF(G10="","",G10/Summary!$B$6) -> 0.0439 | I10: =IF(H10="","",IF(H10<0.1,"Low",IF(H10<1,"Medium","High"))) -> Low | J10: =IF(G10="","",IF(G10>=Summary!$B$7,"Yes","No")) -> No | K10: Kim 2006, J. Environmental Health Sciences | L10: https://www.koreascience.or.kr/article/JAKO200604623620474.page?lang=en
A11: 7 | B11: Hospital WWTP influent | C11: Saudi Arabia (hospital treatment plants) | D11: Maximum | E11: 12.39 | F11: µg/L | G11: =IF(E11="","",E11*IF(F11="ng/L",0.001,IF(F11="mg/L",1000,1))) -> 12.39 | H11: =IF(G11="","",G11/Summary!$B$6) -> 1.239 | I11: =IF(H11="","",IF(H11<0.1,"Low",IF(H11<1,"Medium","High"))) -> High | J11: =IF(G11="","",IF(G11>=Summary!$B$7,"Yes","No")) -> No | K11: Al Qarni et al. 2016, Environmental Science and Pollution Research | L11: https://link.springer.com/article/10.1007/s11356-016-6389-7
A12: 8 | B12: Hospital WWTP effluent | C12: Saudi Arabia | D12: After treatment | G12: =IF(E12="","",E12*IF(F12="ng/L",0.001,IF(F12="mg/L",1000,1))) | H12: =IF(G12="","",G12/Summary!$B$6) | I12: =IF(H12="","",IF(H12<0.1,"Low",IF(H12<1,"Medium","High"))) | J12: =IF(G12="","",IF(G12>=Summary!$B$7,"Yes","No")) | K12: Al Qarni et al. 2016 | L12: https://link.springer.com/article/10.1007/s11356-016-6389-7 | M12: Negligible: more than 98% removed
A13: 9 | B13: Municipal WWTP influent | C13: Mysuru, India | D13: Measured | E13: 4.6 | F13: mg/L | G13: =IF(E13="","",E13*IF(F13="ng/L",0.001,IF(F13="mg/L",1000,1))) -> 4600 | H13: =IF(G13="","",G13/Summary!$B$6) -> 460 | I13: =IF(H13="","",IF(H13<0.1,"Low",IF(H13<1,"Medium","High"))) -> High | J13: =IF(G13="","",IF(G13>=Summary!$B$7,"Yes","No")) -> Yes | K13: Shipingana et al. 2022, Applied Water Science | L13: https://link.springer.com/article/10.1007/s13201-022-01570-1
A14: 10 | B14: Municipal WWTP effluent | C14: Mysuru, India | D14: After treatment | G14: =IF(E14="","",E14*IF(F14="ng/L",0.001,IF(F14="mg/L",1000,1))) | H14: =IF(G14="","",G14/Summary!$B$6) | I14: =IF(H14="","",IF(H14<0.1,"Low",IF(H14<1,"Medium","High"))) | J14: =IF(G14="","",IF(G14>=Summary!$B$7,"Yes","No")) | K14: Shipingana et al. 2022 | L14: https://link.springer.com/article/10.1007/s13201-022-01570-1 | M14: Not detected (about 100% removed)
A15: 11 | B15: WWTP influents worldwide | C15: 5 continents | D15: Lower bound implied by RQ > 800 | E15: =800*Thresholds!$F$5 -> 8000 | F15: µg/L | G15: =IF(E15="","",E15*IF(F15="ng/L",0.001,IF(F15="mg/L",1000,1))) -> 8000 | H15: =IF(G15="","",G15/Summary!$B$6) -> 800 | I15: =IF(H15="","",IF(H15<0.1,"Low",IF(H15<1,"Medium","High"))) -> High | J15: =IF(G15="","",IF(G15>=Summary!$B$7,"Yes","No")) -> Yes | K15: Albarano et al. 2025, J. Hazardous Materials | L15: https://www.iris.unisa.it/handle/11386/4949119 | M15: RQ > 800 with PNEC 10 µg/L means above 8,000 µg/L
A16: 12 | B16: River / estuary | C16: Penang | D16: Not measured yet | G16: =IF(E16="","",E16*IF(F16="ng/L",0.001,IF(F16="mg/L",1000,1))) | H16: =IF(G16="","",G16/Summary!$B$6) | I16: =IF(H16="","",IF(H16<0.1,"Low",IF(H16<1,"Medium","High"))) | J16: =IF(G16="","",IF(G16>=Summary!$B$7,"Yes","No")) | K16: thesis-data-findings (USM theses) | L16: https://repoemc.ukm.my/items/03278d67-ba15-49e1-8dd8-265793d35e3f/full | M16: First data: our CenFac HPLC. (Link: Praveena 2018, Selangor, also did not measure paracetamol)

Sheet Risk_Calculator
A1: Risk calculator: type a concentration, get the risk
A2: Fill in the blue columns (Sample, Concentration, Unit). Units: ng/L, µg/L, ug/L or mg/L. Black columns calculate automatically.
A3: ="Using PNEC = "&Summary!$B$6&" µg/L ("&Summary!$B$5&"); drinking-water limit = "&Summary!$B$7&" µg/L" -> Using PNEC = 10 µg/L (Albarano 2025); drinking-water limit = 175 µg/L
A5: Sample | B5: Concentration | C5: Unit | D5: µg/L | E5: mg/L | F5: RQ | G5: Risk band | H5: vs drinking-water limit
A6: Example: river sample | B6: 120 | C6: ng/L | D6: =IF(OR(B6="",C6=""),"",B6*IF(C6="ng/L",0.001,IF(C6="mg/L",1000,IF(OR(C6="µg/L",C6="ug/L"),1,NA())))) -> 0.12 | E6: =IF(D6="","",D6/1000) -> 0.00012 | F6: =IF(D6="","",D6/Summary!$B$6) -> 0.012 | G6: =IF(F6="","",IF(F6<0.1,"Low",IF(F6<1,"Medium","High"))) -> Low | H6: =IF(D6="","",IF(D6>=Summary!$B$7,"Above","Below")) -> Below
A7: Example: CenFac standard S2 | B7: 0.05 | C7: mg/L | D7: =IF(OR(B7="",C7=""),"",B7*IF(C7="ng/L",0.001,IF(C7="mg/L",1000,IF(OR(C7="µg/L",C7="ug/L"),1,NA())))) -> 50 | E7: =IF(D7="","",D7/1000) -> 0.05 | F7: =IF(D7="","",D7/Summary!$B$6) -> 5 | G7: =IF(F7="","",IF(F7<0.1,"Low",IF(F7<1,"Medium","High"))) -> High | H7: =IF(D7="","",IF(D7>=Summary!$B$7,"Above","Below")) -> Below
D8: =IF(OR(B8="",C8=""),"",B8*IF(C8="ng/L",0.001,IF(C8="mg/L",1000,IF(OR(C8="µg/L",C8="ug/L"),1,NA())))) | E8: =IF(D8="","",D8/1000) | F8: =IF(D8="","",D8/Summary!$B$6) | G8: =IF(F8="","",IF(F8<0.1,"Low",IF(F8<1,"Medium","High"))) | H8: =IF(D8="","",IF(D8>=Summary!$B$7,"Above","Below"))
D9: =IF(OR(B9="",C9=""),"",B9*IF(C9="ng/L",0.001,IF(C9="mg/L",1000,IF(OR(C9="µg/L",C9="ug/L"),1,NA())))) | E9: =IF(D9="","",D9/1000) | F9: =IF(D9="","",D9/Summary!$B$6) | G9: =IF(F9="","",IF(F9<0.1,"Low",IF(F9<1,"Medium","High"))) | H9: =IF(D9="","",IF(D9>=Summary!$B$7,"Above","Below"))
D10: =IF(OR(B10="",C10=""),"",B10*IF(C10="ng/L",0.001,IF(C10="mg/L",1000,IF(OR(C10="µg/L",C10="ug/L"),1,NA())))) | E10: =IF(D10="","",D10/1000) | F10: =IF(D10="","",D10/Summary!$B$6) | G10: =IF(F10="","",IF(F10<0.1,"Low",IF(F10<1,"Medium","High"))) | H10: =IF(D10="","",IF(D10>=Summary!$B$7,"Above","Below"))
D11: =IF(OR(B11="",C11=""),"",B11*IF(C11="ng/L",0.001,IF(C11="mg/L",1000,IF(OR(C11="µg/L",C11="ug/L"),1,NA())))) | E11: =IF(D11="","",D11/1000) | F11: =IF(D11="","",D11/Summary!$B$6) | G11: =IF(F11="","",IF(F11<0.1,"Low",IF(F11<1,"Medium","High"))) | H11: =IF(D11="","",IF(D11>=Summary!$B$7,"Above","Below"))
D12: =IF(OR(B12="",C12=""),"",B12*IF(C12="ng/L",0.001,IF(C12="mg/L",1000,IF(OR(C12="µg/L",C12="ug/L"),1,NA())))) | E12: =IF(D12="","",D12/1000) | F12: =IF(D12="","",D12/Summary!$B$6) | G12: =IF(F12="","",IF(F12<0.1,"Low",IF(F12<1,"Medium","High"))) | H12: =IF(D12="","",IF(D12>=Summary!$B$7,"Above","Below"))
D13: =IF(OR(B13="",C13=""),"",B13*IF(C13="ng/L",0.001,IF(C13="mg/L",1000,IF(OR(C13="µg/L",C13="ug/L"),1,NA())))) | E13: =IF(D13="","",D13/1000) | F13: =IF(D13="","",D13/Summary!$B$6) | G13: =IF(F13="","",IF(F13<0.1,"Low",IF(F13<1,"Medium","High"))) | H13: =IF(D13="","",IF(D13>=Summary!$B$7,"Above","Below"))
D14: =IF(OR(B14="",C14=""),"",B14*IF(C14="ng/L",0.001,IF(C14="mg/L",1000,IF(OR(C14="µg/L",C14="ug/L"),1,NA())))) | E14: =IF(D14="","",D14/1000) | F14: =IF(D14="","",D14/Summary!$B$6) | G14: =IF(F14="","",IF(F14<0.1,"Low",IF(F14<1,"Medium","High"))) | H14: =IF(D14="","",IF(D14>=Summary!$B$7,"Above","Below"))
D15: =IF(OR(B15="",C15=""),"",B15*IF(C15="ng/L",0.001,IF(C15="mg/L",1000,IF(OR(C15="µg/L",C15="ug/L"),1,NA())))) | E15: =IF(D15="","",D15/1000) | F15: =IF(D15="","",D15/Summary!$B$6) | G15: =IF(F15="","",IF(F15<0.1,"Low",IF(F15<1,"Medium","High"))) | H15: =IF(D15="","",IF(D15>=Summary!$B$7,"Above","Below"))
D16: =IF(OR(B16="",C16=""),"",B16*IF(C16="ng/L",0.001,IF(C16="mg/L",1000,IF(OR(C16="µg/L",C16="ug/L"),1,NA())))) | E16: =IF(D16="","",D16/1000) | F16: =IF(D16="","",D16/Summary!$B$6) | G16: =IF(F16="","",IF(F16<0.1,"Low",IF(F16<1,"Medium","High"))) | H16: =IF(D16="","",IF(D16>=Summary!$B$7,"Above","Below"))
D17: =IF(OR(B17="",C17=""),"",B17*IF(C17="ng/L",0.001,IF(C17="mg/L",1000,IF(OR(C17="µg/L",C17="ug/L"),1,NA())))) | E17: =IF(D17="","",D17/1000) | F17: =IF(D17="","",D17/Summary!$B$6) | G17: =IF(F17="","",IF(F17<0.1,"Low",IF(F17<1,"Medium","High"))) | H17: =IF(D17="","",IF(D17>=Summary!$B$7,"Above","Below"))
D18: =IF(OR(B18="",C18=""),"",B18*IF(C18="ng/L",0.001,IF(C18="mg/L",1000,IF(OR(C18="µg/L",C18="ug/L"),1,NA())))) | E18: =IF(D18="","",D18/1000) | F18: =IF(D18="","",D18/Summary!$B$6) | G18: =IF(F18="","",IF(F18<0.1,"Low",IF(F18<1,"Medium","High"))) | H18: =IF(D18="","",IF(D18>=Summary!$B$7,"Above","Below"))
D19: =IF(OR(B19="",C19=""),"",B19*IF(C19="ng/L",0.001,IF(C19="mg/L",1000,IF(OR(C19="µg/L",C19="ug/L"),1,NA())))) | E19: =IF(D19="","",D19/1000) | F19: =IF(D19="","",D19/Summary!$B$6) | G19: =IF(F19="","",IF(F19<0.1,"Low",IF(F19<1,"Medium","High"))) | H19: =IF(D19="","",IF(D19>=Summary!$B$7,"Above","Below"))
... D40: =IF(OR(B40="",C40=""),"",B40*IF(C40="ng/L",0.001,IF(C40="mg/L",1000,IF(OR(C40="µg/L",C40="ug/L"),1,NA())))) | E40: =IF(D40="","",D40/1000) | F40: =IF(D40="","",D40/Summary!$B$6) | G40: =IF(F40="","",IF(F40<0.1,"Low",IF(F40<1,"Medium","High"))) | H40: =IF(D40="","",IF(D40>=Summary!$B$7,"Above","Below"))

Sheet Website_Check
A1: Phi's website: paracetamol (PCM) values vs the literature
A2: Code: frontend/src/core.js, COMPOUNDS_DEFAULT (PCM entry) and the demo site profiles. Suggested values follow the PNEC chosen on the Summary sheet.
A4: Website field | B4: Current value | C4: Current unit | D4: Current (µg/L) | E4: Suggested value | F4: Suggested unit | G4: Suggested (µg/L) | H4: Check | I4: Verdict | J4: Why | K4: Where in code
A5: Screening level ("level") | B5: 0.15 | C5: mg/L | D5: =IF(OR(B5="",ISTEXT(B5)),"",B5*IF(C5="ng/L",0.001,IF(C5="mg/L",1000,1))) -> 150 | E5: =Summary!$B$6/1000 -> 0.01 | F5: mg/L | G5: =IF(OR(E5="",ISTEXT(E5)),"",E5*IF(F5="ng/L",0.001,IF(F5="mg/L",1000,1))) -> 10 | H5: =ROUND(D5/Summary!$B$6,1)&"× the chosen PNEC" -> 15× the chosen PNEC | I5: ❌ Change | J5: No source found. 150 µg/L is close to the human drinking-water limits (175–200 µg/L), not the aquatic-life PNEC. | K5: core.js, PCM: level
A6: PNEC ("pnec") | B6: (empty) | D6: =IF(OR(B6="",ISTEXT(B6)),"",B6*IF(C6="ng/L",0.001,IF(C6="mg/L",1000,1))) | E6: =Summary!$B$6/1000 -> 0.01 | F6: mg/L | G6: =IF(OR(E6="",ISTEXT(E6)),"",E6*IF(F6="ng/L",0.001,IF(F6="mg/L",1000,1))) -> 10 | H6: Not set | I6: ⚠️ Fill in | J6: Without a PNEC the website cannot calculate the risk quotient for paracetamol. | K6: core.js, PCM: pnec
A7: Background ("bg") | B7: 0.012 | C7: mg/L | D7: =IF(OR(B7="",ISTEXT(B7)),"",B7*IF(C7="ng/L",0.001,IF(C7="mg/L",1000,1))) -> 12 | E7: =Measured_Levels!$G$5/1000 -> 4.2e-05 | F7: mg/L | G7: =IF(OR(E7="",ISTEXT(E7)),"",E7*IF(F7="ng/L",0.001,IF(F7="mg/L",1000,1))) -> 0.042 | H7: =ROUND(D7/G7,0)&"× typical clean-river level"&IF(D7>=Summary!$B$6,"; already at or above the PNEC","") -> 286× typical clean-river level; already at or above the PNEC | I7: ❌ Change | J7: Typical river level = US median detection (Measured_Levels row 1). | K7: core.js, PCM: bg
A8: Demo site SP1 (hospital drain) | B8: 0.38 | C8: mg/L | D8: =IF(OR(B8="",ISTEXT(B8)),"",B8*IF(C8="ng/L",0.001,IF(C8="mg/L",1000,1))) -> 380 | E8: =B8 -> 0.38 | F8: =C8 -> mg/L | G8: =IF(OR(E8="",ISTEXT(E8)),"",E8*IF(F8="ng/L",0.001,IF(F8="mg/L",1000,1))) -> 380 | H8: =ROUND(D8/Summary!$B$6,0)&"× the chosen PNEC" -> 38× the chosen PNEC | I8: ⚠️ Label as estimate | J8: Only realistic for raw sewage or a hospital drain (hospital influent max 12.4 µg/L in Saudi Arabia; city influent 4,600 µg/L in India). | K8: core.js, site profiles: prof.PCM
A9: Demo site SP2 (Kampung Rawa) | B9: 0.3 | C9: mg/L | D9: =IF(OR(B9="",ISTEXT(B9)),"",B9*IF(C9="ng/L",0.001,IF(C9="mg/L",1000,1))) -> 300 | E9: =B9 -> 0.3 | F9: =C9 -> mg/L | G9: =IF(OR(E9="",ISTEXT(E9)),"",E9*IF(F9="ng/L",0.001,IF(F9="mg/L",1000,1))) -> 300 | H9: =ROUND(D9/Summary!$B$6,0)&"× the chosen PNEC" -> 30× the chosen PNEC | I9: ⚠️ Label as estimate | J9: Unsewered settlement: plausible near the drain, high for the river itself. | K9: core.js, site profiles: prof.PCM
A10: Demo site SP3 (city drains) | B10: 0.16 | C10: mg/L | D10: =IF(OR(B10="",ISTEXT(B10)),"",B10*IF(C10="ng/L",0.001,IF(C10="mg/L",1000,1))) -> 160 | E10: =B10 -> 0.16 | F10: =C10 -> mg/L | G10: =IF(OR(E10="",ISTEXT(E10)),"",E10*IF(F10="ng/L",0.001,IF(F10="mg/L",1000,1))) -> 160 | H10: =ROUND(D10/Summary!$B$6,0)&"× the chosen PNEC" -> 16× the chosen PNEC | I10: ⚠️ Label as estimate | J10: Same as above. | K10: core.js, site profiles: prof.PCM
A11: Demo site Jelutong STP | B11: 0.03 | C11: mg/L | D11: =IF(OR(B11="",ISTEXT(B11)),"",B11*IF(C11="ng/L",0.001,IF(C11="mg/L",1000,1))) -> 30 | E11: 0.0001 | F11: mg/L | G11: =IF(OR(E11="",ISTEXT(E11)),"",E11*IF(F11="ng/L",0.001,IF(F11="mg/L",1000,1))) -> 0.1 | H11: =ROUND(D11/Summary!$B$6,1)&"× the chosen PNEC" -> 3× the chosen PNEC | I11: ❌ Lower | J11: Treatment removes more than 98% of paracetamol (Saudi and Indian studies), so treated effluent should be far lower than 30 µg/L. 0.1 µg/L is an illustrative placeholder. | K11: core.js, site profiles: prof.PCM
A12: Unit ("unit") | B12: mg/L | E12: µg/L | H12: Other medicines use µg/L | I12: ⚠️ Switch | J12: One unit for all medicines avoids 1,000× mistakes. | K12: core.js, PCM: unit

Sheet Lab_Design
A1: CenFac experiment: paracetamol standards and dilution plan
A2: Change the blue inputs; volumes recalculate. Stock A is weighed; B and C are diluted from it so every pipette volume stays above your smallest accurate volume.
A4: INPUTS
A5: Stock A concentration (mg/L) | B5: 1000
A6: Stock A volume (mL) | B6: 100
A7: Paracetamol purity (analytical grade) | B7: 0.99
A8: → Paracetamol to weigh for Stock A (mg) | B8: =B5*B6/1000/B7 -> 101.0101
A9: Stock B concentration (mg/L) | B9: 10
A10: Stock B volume (mL) | B10: 100
A11: → Stock A needed for Stock B (mL) | B11: =B9*B10/B5 -> 1
A12: Stock C concentration (mg/L) | B12: 0.1
A13: Stock C volume (mL) | B13: 100
A14: → Stock B needed for Stock C (mL) | B14: =B12*B13/B9 -> 1
A15: Final volume of each standard (mL) | B15: 50
A16: Smallest volume you can pipette accurately (mL) | B16: 0.1
A17: Replicates per standard | B17: 3
A18: Solvent | B18: Ultrapure (Milli-Q) water
A20: Standard | B20: Target (mg/L) | C20: Target (µg/L) | D20: Measure with | E20: What it represents | F20: Stock to use | G20: Stock conc. (mg/L) | H20: Stock volume (mL) | I20: Solvent to add (mL) | J20: RQ (vs chosen PNEC) | K20: Risk band | L20: Check
A21: S0 | B21: 0 | C21: =B21*1000 -> 0 | D21: All (blank) | E21: Blank: solvent only, for baseline | F21: =IF(B21=0,"none",IF(B21*$B$15/$B$5>=$B$16,"A",IF(B21*$B$15/$B$9>=$B$16,"B","C"))) -> none | G21: =IF(F21="A",$B$5,IF(F21="B",$B$9,IF(F21="C",$B$12,0))) -> 0 | H21: =IF(G21=0,0,B21*$B$15/G21) -> 0 | I21: =$B$15-H21 -> 50 | J21: =C21/Summary!$B$6 -> 0 | K21: =IF(J21<0.1,"Low",IF(J21<1,"Medium","High")) -> Low | L21: =IF(AND(H21>0,H21<$B$16),"Volume too small: make a weaker stock",IF(H21>$B$15,"Stock too weak","OK")) -> OK
A22: S1 | B22: 0.01 | C22: =B22*1000 -> 10 | D22: HPLC | E22: PNEC (Albarano 2025): the "bad" line for aquatic life | F22: =IF(B22=0,"none",IF(B22*$B$15/$B$5>=$B$16,"A",IF(B22*$B$15/$B$9>=$B$16,"B","C"))) -> C | G22: =IF(F22="A",$B$5,IF(F22="B",$B$9,IF(F22="C",$B$12,0))) -> 0.1 | H22: =IF(G22=0,0,B22*$B$15/G22) -> 5 | I22: =$B$15-H22 -> 45 | J22: =C22/Summary!$B$6 -> 1 | K22: =IF(J22<0.1,"Low",IF(J22<1,"Medium","High")) -> High | L22: =IF(AND(H22>0,H22<$B$16),"Volume too small: make a weaker stock",IF(H22>$B$15,"Stock too weak","OK")) -> OK
A23: S2 | B23: 0.05 | C23: =B23*1000 -> 50 | D23: HPLC | E23: HC5: 5% of species affected | F23: =IF(B23=0,"none",IF(B23*$B$15/$B$5>=$B$16,"A",IF(B23*$B$15/$B$9>=$B$16,"B","C"))) -> B | G23: =IF(F23="A",$B$5,IF(F23="B",$B$9,IF(F23="C",$B$12,0))) -> 10 | H23: =IF(G23=0,0,B23*$B$15/G23) -> 0.25 | I23: =$B$15-H23 -> 49.75 | J23: =C23/Summary!$B$6 -> 5 | K23: =IF(J23<0.1,"Low",IF(J23<1,"Medium","High")) -> High | L23: =IF(AND(H23>0,H23<$B$16),"Volume too small: make a weaker stock",IF(H23>$B$15,"Stock too weak","OK")) -> OK
A24: S3 | B24: 0.1 | C24: =B24*1000 -> 100 | D24: HPLC | E24: Between HC5 and the drinking-water limit (0.175 mg/L) | F24: =IF(B24=0,"none",IF(B24*$B$15/$B$5>=$B$16,"A",IF(B24*$B$15/$B$9>=$B$16,"B","C"))) -> B | G24: =IF(F24="A",$B$5,IF(F24="B",$B$9,IF(F24="C",$B$12,0))) -> 10 | H24: =IF(G24=0,0,B24*$B$15/G24) -> 0.5 | I24: =$B$15-H24 -> 49.5 | J24: =C24/Summary!$B$6 -> 10 | K24: =IF(J24<0.1,"Low",IF(J24<1,"Medium","High")) -> High | L24: =IF(AND(H24>0,H24<$B$16),"Volume too small: make a weaker stock",IF(H24>$B$15,"Stock too weak","OK")) -> OK
A25: S4 | B25: 0.5 | C25: =B25*1000 -> 500 | D25: HPLC | E25: Raw sewage / hospital drain level | F25: =IF(B25=0,"none",IF(B25*$B$15/$B$5>=$B$16,"A",IF(B25*$B$15/$B$9>=$B$16,"B","C"))) -> B | G25: =IF(F25="A",$B$5,IF(F25="B",$B$9,IF(F25="C",$B$12,0))) -> 10 | H25: =IF(G25=0,0,B25*$B$15/G25) -> 2.5 | I25: =$B$15-H25 -> 47.5 | J25: =C25/Summary!$B$6 -> 50 | K25: =IF(J25<0.1,"Low",IF(J25<1,"Medium","High")) -> High | L25: =IF(AND(H25>0,H25<$B$16),"Volume too small: make a weaker stock",IF(H25>$B$15,"Stock too weak","OK")) -> OK
A26: S5 | B26: 1 | C26: =B26*1000 -> 1000 | D26: HPLC + UV-Vis | E26: Overlap point 1 (UV-Vis near its LOQ, 0.98 mg/L) | F26: =IF(B26=0,"none",IF(B26*$B$15/$B$5>=$B$16,"A",IF(B26*$B$15/$B$9>=$B$16,"B","C"))) -> B | G26: =IF(F26="A",$B$5,IF(F26="B",$B$9,IF(F26="C",$B$12,0))) -> 10 | H26: =IF(G26=0,0,B26*$B$15/G26) -> 5 | I26: =$B$15-H26 -> 45 | J26: =C26/Summary!$B$6 -> 100 | K26: =IF(J26<0.1,"Low",IF(J26<1,"Medium","High")) -> High | L26: =IF(AND(H26>0,H26<$B$16),"Volume too small: make a weaker stock",IF(H26>$B$15,"Stock too weak","OK")) -> OK
A27: S6 | B27: 2 | C27: =B27*1000 -> 2000 | D27: UV-Vis | E27: Start of UV-Vis linear range (2 mg/L) | F27: =IF(B27=0,"none",IF(B27*$B$15/$B$5>=$B$16,"A",IF(B27*$B$15/$B$9>=$B$16,"B","C"))) -> A | G27: =IF(F27="A",$B$5,IF(F27="B",$B$9,IF(F27="C",$B$12,0))) -> 1000 | H27: =IF(G27=0,0,B27*$B$15/G27) -> 0.1 | I27: =$B$15-H27 -> 49.9 | J27: =C27/Summary!$B$6 -> 200 | K27: =IF(J27<0.1,"Low",IF(J27<1,"Medium","High")) -> High | L27: =IF(AND(H27>0,H27<$B$16),"Volume too small: make a weaker stock",IF(H27>$B$15,"Stock too weak","OK")) -> OK
A28: S7 | B28: 5 | C28: =B28*1000 -> 5000 | D28: HPLC + UV-Vis | E28: Overlap point 2 | F28: =IF(B28=0,"none",IF(B28*$B$15/$B$5>=$B$16,"A",IF(B28*$B$15/$B$9>=$B$16,"B","C"))) -> A | G28: =IF(F28="A",$B$5,IF(F28="B",$B$9,IF(F28="C",$B$12,0))) -> 1000 | H28: =IF(G28=0,0,B28*$B$15/G28) -> 0.25 | I28: =$B$15-H28 -> 49.75 | J28: =C28/Summary!$B$6 -> 500 | K28: =IF(J28<0.1,"Low",IF(J28<1,"Medium","High")) -> High | L28: =IF(AND(H28>0,H28<$B$16),"Volume too small: make a weaker stock",IF(H28>$B$15,"Stock too weak","OK")) -> OK
A29: S8 | B29: 10 | C29: =B29*1000 -> 10000 | D29: HPLC + UV-Vis | E29: Overlap point 3; dilute 10× before HPLC if above its calibrated range | F29: =IF(B29=0,"none",IF(B29*$B$15/$B$5>=$B$16,"A",IF(B29*$B$15/$B$9>=$B$16,"B","C"))) -> A | G29: =IF(F29="A",$B$5,IF(F29="B",$B$9,IF(F29="C",$B$12,0))) -> 1000 | H29: =IF(G29=0,0,B29*$B$15/G29) -> 0.5 | I29: =$B$15-H29 -> 49.5 | J29: =C29/Summary!$B$6 -> 1000 | K29: =IF(J29<0.1,"Low",IF(J29<1,"Medium","High")) -> High | L29: =IF(AND(H29>0,H29<$B$16),"Volume too small: make a weaker stock",IF(H29>$B$15,"Stock too weak","OK")) -> OK
A30: S9 | B30: 15 | C30: =B30*1000 -> 15000 | D30: UV-Vis | E30: UV-Vis calibration | F30: =IF(B30=0,"none",IF(B30*$B$15/$B$5>=$B$16,"A",IF(B30*$B$15/$B$9>=$B$16,"B","C"))) -> A | G30: =IF(F30="A",$B$5,IF(F30="B",$B$9,IF(F30="C",$B$12,0))) -> 1000 | H30: =IF(G30=0,0,B30*$B$15/G30) -> 0.75 | I30: =$B$15-H30 -> 49.25 | J30: =C30/Summary!$B$6 -> 1500 | K30: =IF(J30<0.1,"Low",IF(J30<1,"Medium","High")) -> High | L30: =IF(AND(H30>0,H30<$B$16),"Volume too small: make a weaker stock",IF(H30>$B$15,"Stock too weak","OK")) -> OK
A31: S10 | B31: 20 | C31: =B31*1000 -> 20000 | D31: UV-Vis | E31: UV-Vis calibration | F31: =IF(B31=0,"none",IF(B31*$B$15/$B$5>=$B$16,"A",IF(B31*$B$15/$B$9>=$B$16,"B","C"))) -> A | G31: =IF(F31="A",$B$5,IF(F31="B",$B$9,IF(F31="C",$B$12,0))) -> 1000 | H31: =IF(G31=0,0,B31*$B$15/G31) -> 1 | I31: =$B$15-H31 -> 49 | J31: =C31/Summary!$B$6 -> 2000 | K31: =IF(J31<0.1,"Low",IF(J31<1,"Medium","High")) -> High | L31: =IF(AND(H31>0,H31<$B$16),"Volume too small: make a weaker stock",IF(H31>$B$15,"Stock too weak","OK")) -> OK
A32: S11 | B32: 24 | C32: =B32*1000 -> 24000 | D32: UV-Vis | E32: End of UV-Vis linear range (24 mg/L) | F32: =IF(B32=0,"none",IF(B32*$B$15/$B$5>=$B$16,"A",IF(B32*$B$15/$B$9>=$B$16,"B","C"))) -> A | G32: =IF(F32="A",$B$5,IF(F32="B",$B$9,IF(F32="C",$B$12,0))) -> 1000 | H32: =IF(G32=0,0,B32*$B$15/G32) -> 1.2 | I32: =$B$15-H32 -> 48.8 | J32: =C32/Summary!$B$6 -> 2400 | K32: =IF(J32<0.1,"Low",IF(J32<1,"Medium","High")) -> High | L32: =IF(AND(H32>0,H32<$B$16),"Volume too small: make a weaker stock",IF(H32>$B$15,"Stock too weak","OK")) -> OK
A34: Totals
A35: Standards | B35: =COUNTA(A21:A32) -> 12
A36: Preparations incl. replicates | B36: =B35*$B$17 -> 36
A37: HPLC vials needed (incl. replicates) | B37: =(COUNTIF(D21:D32,"*HPLC*")+COUNTIF(D21:D32,"All*"))*$B$17 -> 24
A38: UV-Vis measurements (incl. replicates) | B38: =(COUNTIF(D21:D32,"*UV-Vis*")+COUNTIF(D21:D32,"All*"))*$B$17 -> 24
A40: NOTES
A41: 1. Stock A: weigh the paracetamol (row 8), dissolve in the solvent in a volumetric flask and fill to the mark. Paracetamol dissolves easily in water (about 14 g/L at 25 °C, a textbook value: check the SDS).
A42: 2. Stock B = Stock A diluted (row 11 volume into row 10 flask). Stock C = Stock B diluted (row 14 into row 13). Then make each standard from the stock in column F.
A43: 3. Paracetamol is neutral at pH 7 (pKa about 9.5): in clean standards it barely changes pH or conductivity, so UV is the only sensor expected to respond. Record pH and conductivity anyway (Results_Log).
A44: 4. HPLC: Nguyen et al. (2023) validated 0.01–1 mg/L at 243 nm. Ask CenFac for their calibrated range and LOD; dilute standards above it before injection.
...

Sheet Results_Log
A1: Results log: one row per measurement
A2: Fill in the blue columns after each measurement. Target and recovery calculate automatically. Row 6 is an EXAMPLE with made-up values: delete it before use.
A5: Date | B5: Standard | C5: Replicate | D5: Target (mg/L) | E5: pH | F5: Conductivity (µS/cm) | G5: Temperature (°C) | H5: UV absorbance (243 nm) | I5: HPLC result (mg/L) | J5: HPLC recovery | K5: Notes
A6: 2026-10-10 | B6: S5 | C6: 1 | D6: =IF(B6="","",INDEX(Lab_Design!$B$21:$B$32,MATCH(B6,Lab_Design!$A$21:$A$32,0))) -> 1 | E6: 6.8 | F6: 2.1 | G6: 25 | H6: 0.064 | I6: 0.98 | J6: =IF(OR(I6="",D6="",D6=0),"",I6/D6) -> 0.98 | K6: EXAMPLE ROW (made-up values): delete before use
D7: =IF(B7="","",INDEX(Lab_Design!$B$21:$B$32,MATCH(B7,Lab_Design!$A$21:$A$32,0))) | J7: =IF(OR(I7="",D7="",D7=0),"",I7/D7)
D8: =IF(B8="","",INDEX(Lab_Design!$B$21:$B$32,MATCH(B8,Lab_Design!$A$21:$A$32,0))) | J8: =IF(OR(I8="",D8="",D8=0),"",I8/D8)
D9: =IF(B9="","",INDEX(Lab_Design!$B$21:$B$32,MATCH(B9,Lab_Design!$A$21:$A$32,0))) | J9: =IF(OR(I9="",D9="",D9=0),"",I9/D9)
D10: =IF(B10="","",INDEX(Lab_Design!$B$21:$B$32,MATCH(B10,Lab_Design!$A$21:$A$32,0))) | J10: =IF(OR(I10="",D10="",D10=0),"",I10/D10)
D11: =IF(B11="","",INDEX(Lab_Design!$B$21:$B$32,MATCH(B11,Lab_Design!$A$21:$A$32,0))) | J11: =IF(OR(I11="",D11="",D11=0),"",I11/D11)
D12: =IF(B12="","",INDEX(Lab_Design!$B$21:$B$32,MATCH(B12,Lab_Design!$A$21:$A$32,0))) | J12: =IF(OR(I12="",D12="",D12=0),"",I12/D12)
D13: =IF(B13="","",INDEX(Lab_Design!$B$21:$B$32,MATCH(B13,Lab_Design!$A$21:$A$32,0))) | J13: =IF(OR(I13="",D13="",D13=0),"",I13/D13)
D14: =IF(B14="","",INDEX(Lab_Design!$B$21:$B$32,MATCH(B14,Lab_Design!$A$21:$A$32,0))) | J14: =IF(OR(I14="",D14="",D14=0),"",I14/D14)
D15: =IF(B15="","",INDEX(Lab_Design!$B$21:$B$32,MATCH(B15,Lab_Design!$A$21:$A$32,0))) | J15: =IF(OR(I15="",D15="",D15=0),"",I15/D15)
D16: =IF(B16="","",INDEX(Lab_Design!$B$21:$B$32,MATCH(B16,Lab_Design!$A$21:$A$32,0))) | J16: =IF(OR(I16="",D16="",D16=0),"",I16/D16)
D17: =IF(B17="","",INDEX(Lab_Design!$B$21:$B$32,MATCH(B17,Lab_Design!$A$21:$A$32,0))) | J17: =IF(OR(I17="",D17="",D17=0),"",I17/D17)
D18: =IF(B18="","",INDEX(Lab_Design!$B$21:$B$32,MATCH(B18,Lab_Design!$A$21:$A$32,0))) | J18: =IF(OR(I18="",D18="",D18=0),"",I18/D18)
... D80: =IF(B80="","",INDEX(Lab_Design!$B$21:$B$32,MATCH(B80,Lab_Design!$A$21:$A$32,0))) | J80: =IF(OR(I80="",D80="",D80=0),"",I80/D80)

Sheet Instrument_Limits
A1: What can the instruments see?
A2: LOD = lowest level detected; LOQ = lowest level measured reliably. Values are for the solution put into the instrument.
A4: Instrument | B4: Wavelength (nm) | C4: Linear from (mg/L) | D4: Linear to (mg/L) | E4: LOD (mg/L) | F4: LOQ (mg/L) | G4: LOQ (µg/L) | H4: Can it measure the PNEC? | I4: Can it measure a typical river level? | J4: Sample prep | K4: Source | L4: Link
A5: UV-Vis spectrophotometer | B5: 246 | C5: 2 | D5: 24 | E5: 0.3275 | F5: 0.9836 | G5: =IF(F5="","",F5*1000) -> 983.6 | H5: =IF(G5="","",IF(G5<=Summary!$B$6,"Yes","No: LOQ is "&ROUND(G5/Summary!$B$6,0)&"× the PNEC")) -> No: LOQ is 98× the PNEC | I5: =IF(G5="","",IF(G5<=Measured_Levels!$G$5,"Yes","No: needs "&ROUND(G5/Measured_Levels!$G$5,0)&"× concentration")) -> No: needs 23419× concentration | J5: None (bulk powder and tablets) | K5: Sharma et al. 2013, Oriental Journal of Chemistry | L5: https://www.orientjchem.org/?p=11983
A6: HPLC-UV, C18 column | B6: 243 | C6: 0.01 | D6: 1 | E6: 0.003 | F6: 0.01 | G6: =IF(F6="","",F6*1000) -> 10 | H6: =IF(G6="","",IF(G6<=Summary!$B$6,"Yes","No: LOQ is "&ROUND(G6/Summary!$B$6,0)&"× the PNEC")) -> Yes | I6: =IF(G6="","",IF(G6<=Measured_Levels!$G$5,"Yes","No: needs "&ROUND(G6/Measured_Levels!$G$5,0)&"× concentration")) -> No: needs 238× concentration | J6: Solid-phase extraction (SPE), recovery above 95% | K6: Nguyen et al. 2023, Vietnam Journal of Science and Technology 61(4) | L6: https://vjs.ac.vn/jst/article/view/16418
A7: CenFac HPLC (ask CenFac and fill in) | G7: =IF(F7="","",F7*1000) | H7: =IF(G7="","",IF(G7<=Summary!$B$6,"Yes","No: LOQ is "&ROUND(G7/Summary!$B$6,0)&"× the PNEC")) | I7: =IF(G7="","",IF(G7<=Measured_Levels!$G$5,"Yes","No: needs "&ROUND(G7/Measured_Levels!$G$5,0)&"× concentration")) | K7: CenFac
A9: SPE CONCENTRATION (for real river samples)
A10: SPE concentration factor (e.g. 500 mL water → 1 mL extract = 500) | B10: 500
A11: HPLC-UV LOQ in the river water after SPE (µg/L) | B11: =G6/B10 -> 0.02
A12: Can HPLC + SPE then measure a typical river level? | B12: =IF(B11<=Measured_Levels!$G$5,"Yes","No") -> Yes
A14: Take-away: UV-Vis only sees sewage or spill levels (mg/L). HPLC-UV reaches the PNEC directly, and typical river levels only after SPE.

Sheet Sources
A1: Sources
A3: # | B3: Reference | C3: Used for | D3: Link
A4: 1 | B4: Albarano L., Maggio C., Lofrano G., Carotenuto M., Guida M., Vaiano V., Libralato G. (2025). Environmental risk assessment of paracetamol in aquatic ecosystems using species sensitivity distribution and global occurrence data. Journal of Hazardous Materials. doi 10.1016/j.jhazmat.2025.140107 | C4: PNEC 10 µg/L, HC5 50 µg/L, influent RQ > 800 | D4: https://www.iris.unisa.it/handle/11386/4949119
A5: 2 | B5: Environmental Sciences Europe (2024). Is environmental risk assessment possible with the alternatives to acute fish toxicity test? Case study with pharmaceuticals. Table 4 (NORMAN PNECs). | C5: NORMAN lowest long-term freshwater PNEC 46 µg/L | D5: https://enveurope.springeropen.com/articles/10.1186/s12302-024-01015-3/tables/4
A6: 3 | B6: Shipingana L.N.N., Shivaraju H.P., Yashas S.R. (2022). Quantitative assessment of pharmaceutical drugs in a municipal wastewater and overview of associated risks. Applied Water Science. | C6: Mysuru influent 4.6 mg/L, PNEC 12.9 µg/L | D6: https://link.springer.com/article/10.1007/s13201-022-01570-1
A7: 4 | B7: Fan H. et al. (2022). Derivation of predicted no-effect concentrations for thirty-five pharmaceuticals and personal care products in freshwater ecosystem. | C7: Chronic HC5 1.21 mg/L | D7: https://www.frontiersin.org/journals/marine-science/articles/10.3389/fmars.2022.1043792/pdf
A8: 5 | B8: Kim P.-G. (2006). Ecotoxicological risk assessment for acetaminophen in Kyongahn River. Journal of Environmental Health Sciences. | C8: Daphnia LC50 16.9 mg/L; river 0.439 µg/L | D8: https://www.koreascience.or.kr/article/JAKO200604623620474.page?lang=en
A9: 6 | B9: EPA Victoria (2023). Appendix A: Emerging contaminants in recycled water, Table 12 (Australian Guidelines for Water Recycling 2008). | C9: Drinking-water guideline 175 µg/L | D9: https://app.production.epa-vic-gov-au.sdp3.sdp.vic.gov.au/sites/default/files/epa/publications/appendix_a_emerging-contaminants-in-recycled-water_31may2023.pdf
A10: 7 | B10: Minnesota Department of Health (2015). Toxicological summary for acetaminophen. | C10: Drinking-water guidance 200 µg/L | D10: https://www.health.mn.gov/communities/environment/risk/docs/guidance/dwec/sumacetamin.pdf
A11: 8 | B11: Al-Odaini N.A., Zakaria M.P., Yaziz M.I., Surif S., Abdulghani M. (2013). The occurrence of human pharmaceuticals in wastewater effluents and surface water of Langat River and its tributaries, Malaysia. Int. J. Environmental Analytical Chemistry. | C11: Langat River max 346.3 ng/L | D11: https://www.ingentaconnect.com/content/tandf/geac/2013/00000093/00000003/art00001
A12: 9 | B12: Al Qarni H., Collier P., O'Keeffe J., Akunna J. (2016). Investigating the removal of some pharmaceutical compounds in hospital wastewater treatment plants operating in Saudi Arabia. Environmental Science and Pollution Research. | C12: Hospital influent up to 12.4 µg/L; >98% removal | D12: https://link.springer.com/article/10.1007/s11356-016-6389-7
A13: 10 | B13: US Water Quality Portal (USGS, EPA). AquaTrace analysis of paired river data, 1999–2025 (wqp_paired_streams.csv). | C13: US river distribution: median 42 ng/L, max 76 µg/L | D13: https://www.waterqualitydata.us/
A14: 11 | B14: Sharma S. et al. (2013). Development and validation of a UV spectroscopic method for analysis of paracetamol in bulk powder and tablet. Oriental Journal of Chemistry. | C14: UV-Vis 246 nm, linear 2–24 mg/L, LOD 0.33 mg/L | D14: https://www.orientjchem.org/?p=11983
A15: 12 | B15: Nguyen T.D. et al. (2023). Simultaneous determination of paracetamol and diclofenac in wastewater by high-performance liquid chromatography method. Vietnam Journal of Science and Technology 61(4), 599–608. | C15: HPLC-UV 243 nm, LOQ 0.01 mg/L, SPE | D15: https://vjs.ac.vn/jst/article/view/16418
A16: 13 | B16: Praveena S.M. et al. (2018). Pharmaceuticals residues in selected tropical surface water bodies from Selangor (Malaysia). Science of the Total Environment. | C16: Shows paracetamol was not measured in Selangor | D16: https://repoemc.ukm.my/items/03278d67-ba15-49e1-8dd8-265793d35e3f/full
